Workbook

Sheet Inputs
A1: 📞 Phone Phoebe — Business Assumptions | Yellow = change these
A2: ✏️ Edit any yellow cell — the Monthly Model and Unit Economics sheets update automatically
A4: 1 — PRICING TIERS
B5: Basic plan price | C5: 39 | D5: £/month
B6: Professional plan price | C6: 89 | D6: £/month
B7: Premium plan price | C7: 189 | D7: £/month
A9: 2 — CLIENT PLAN MIX (must add to 100%)
B10: % of clients on Basic | C10: 0.7 | D10: e.g. 0.70 = 70%
B11: % of clients on Professional | C11: 0.25 | D11: e.g. 0.25 = 25%
B12: % of clients on Premium | C12: 0.05 | D12: e.g. 0.05 = 5%
B13: ▶ Blended ARPU (auto) | C13: =C5*C10+C6*C11+C7*C12 | D13: £/client/month
A15: 3 — VARIABLE COST PER CALL
B16: All-in API cost per minute | C16: 0.11 | D16: £/min (Vapi+Deepgram+GPT+11labs)
B17: Average call duration | C17: 3 | D17: minutes
B18: Average calls per client/month | C18: 30 | D18: calls
B19: ▶ Variable COGS per client (auto) | C19: =C16*C17*C18 | D19: £/month
A21: 4 — FIXED COSTS PER CLIENT / MONTH
B22: Vapi phone number | C22: 1.6 | D22: £/month
B23: Hosting (Railway share/client) | C23: 1.5 | D23: £/month
B24: ElevenLabs voice share | C24: 1.5 | D24: £/month
B25: Cal.com (client's own free plan) | C25: 0 | D25: £/month
B26: ▶ Fixed per client (auto) | C26: =SUM(C22:C25) | D26: £/month
B27: ▶ ALL-IN COGS per client (auto) | C27: =C19+C26 | D27: £/month — your true cost per client
A29: 5 — MONTHLY OVERHEAD (your fixed running costs)
B30: Facebook / Instagram ads | C30: 200 | D30: £/month
B31: Railway server hosting | C31: 5 | D31: £/month
B32: ElevenLabs Creator plan | C32: 18 | D32: £/month
B33: Domain + tools + misc | C33: 10 | D33: £/month
B34: ▶ Total overhead (auto) | C34: =SUM(C30:C33) | D34: £/month
A36: 6 — CUSTOMER ACQUISITION & GROWTH
B37: Cost per lead (Facebook ads) | C37: 5 | D37: £/lead
B38: Lead → trial start rate | C38: 0.25 | D38: %
B39: Trial → paid rate ← KEY NUMBER | C39: 0.25 | D39: % (most important variable)
B40: ▶ New paid clients/mo from ads (auto) | C40: =(C30/C37)*C38*C39 | D40: clients/month
B41: Organic / referral (from month 5) | C41: 1 | D41: clients/month
B42: Monthly churn rate | C42: 0.03 | D42: % (0.03 = lose 3 in every 100)
A44: QUICK REFERENCE — BREAK-EVEN CLIENTS
B45: ▶ Clients needed to break even (auto) | C45: =CEILING(C34/(C13-C27),1) | D45: clients — once you hit this, you're profitable
B46: ▶ CAC (cost to acquire 1 client, auto) | C46: =IF(C40>0,C30/C40,0) | D46: £
B47: ▶ LTV at 3% churn (auto) | C47: =(1/C42)*C13 | D47: £ (33-month avg lifetime × ARPU)
...

Sheet Monthly Model
A1: 📅 Phone Phoebe — 12-Month Revenue Model (change numbers in Inputs sheet)
A2: All figures in £ GBP · Formulas auto-update from Inputs · Green = profit · Red = loss
B4: Mo | C4: New (Ads) | D4: New (Organic) | E4: Total New | F4: Churned | G4: Active Clients | H4: ARPU £ | I4: MRR £ | J4: COGS £ | K4: Gross Profit £ | L4: Margin % | M4: Overhead £ | N4: Net P&L £ | O4: Cumulative £
B5: 1 | C5: =ROUND('Inputs'!C40,0) | D5: 0 | E5: =C5+D5 | F5: =0 | G5: =E5-F5 | H5: ='Inputs'!C13 | I5: =G5*H5 | J5: =G5*'Inputs'!C27 | K5: =I5-J5 | L5: =IF(I5>0,K5/I5,0) | M5: ='Inputs'!C34 | N5: =K5-M5 | O5: =N5
B6: 2 | C6: =ROUND('Inputs'!C40,0) | D6: 0 | E6: =C6+D6 | F6: =ROUND(G5*'Inputs'!C42,0) | G6: =G5+E6-F6 | H6: ='Inputs'!C13 | I6: =G6*H6 | J6: =G6*'Inputs'!C27 | K6: =I6-J6 | L6: =IF(I6>0,K6/I6,0) | M6: ='Inputs'!C34 | N6: =K6-M6 | O6: =O5+N6
B7: 3 | C7: =ROUND('Inputs'!C40,0) | D7: 0 | E7: =C7+D7 | F7: =ROUND(G6*'Inputs'!C42,0) | G7: =G6+E7-F7 | H7: ='Inputs'!C13 | I7: =G7*H7 | J7: =G7*'Inputs'!C27 | K7: =I7-J7 | L7: =IF(I7>0,K7/I7,0) | M7: ='Inputs'!C34 | N7: =K7-M7 | O7: =O6+N7
B8: 4 | C8: =ROUND('Inputs'!C40,0) | D8: 0 | E8: =C8+D8 | F8: =ROUND(G7*'Inputs'!C42,0) | G8: =G7+E8-F8 | H8: ='Inputs'!C13 | I8: =G8*H8 | J8: =G8*'Inputs'!C27 | K8: =I8-J8 | L8: =IF(I8>0,K8/I8,0) | M8: ='Inputs'!C34 | N8: =K8-M8 | O8: =O7+N8
B9: 5 | C9: =ROUND('Inputs'!C40,0) | D9: ='Inputs'!C41 | E9: =C9+D9 | F9: =ROUND(G8*'Inputs'!C42,0) | G9: =G8+E9-F9 | H9: ='Inputs'!C13 | I9: =G9*H9 | J9: =G9*'Inputs'!C27 | K9: =I9-J9 | L9: =IF(I9>0,K9/I9,0) | M9: ='Inputs'!C34 | N9: =K9-M9 | O9: =O8+N9
B10: 6 | C10: =ROUND('Inputs'!C40,0) | D10: ='Inputs'!C41 | E10: =C10+D10 | F10: =ROUND(G9*'Inputs'!C42,0) | G10: =G9+E10-F10 | H10: ='Inputs'!C13 | I10: =G10*H10 | J10: =G10*'Inputs'!C27 | K10: =I10-J10 | L10: =IF(I10>0,K10/I10,0) | M10: ='Inputs'!C34 | N10: =K10-M10 | O10: =O9+N10
B11: 7 | C11: =ROUND('Inputs'!C40,0) | D11: ='Inputs'!C41 | E11: =C11+D11 | F11: =ROUND(G10*'Inputs'!C42,0) | G11: =G10+E11-F11 | H11: ='Inputs'!C13 | I11: =G11*H11 | J11: =G11*'Inputs'!C27 | K11: =I11-J11 | L11: =IF(I11>0,K11/I11,0) | M11: ='Inputs'!C34 | N11: =K11-M11 | O11: =O10+N11
B12: 8 | C12: =ROUND('Inputs'!C40,0) | D12: ='Inputs'!C41 | E12: =C12+D12 | F12: =ROUND(G11*'Inputs'!C42,0) | G12: =G11+E12-F12 | H12: ='Inputs'!C13 | I12: =G12*H12 | J12: =G12*'Inputs'!C27 | K12: =I12-J12 | L12: =IF(I12>0,K12/I12,0) | M12: ='Inputs'!C34 | N12: =K12-M12 | O12: =O11+N12
B13: 9 | C13: =ROUND('Inputs'!C40,0) | D13: ='Inputs'!C41 | E13: =C13+D13 | F13: =ROUND(G12*'Inputs'!C42,0) | G13: =G12+E13-F13 | H13: ='Inputs'!C13 | I13: =G13*H13 | J13: =G13*'Inputs'!C27 | K13: =I13-J13 | L13: =IF(I13>0,K13/I13,0) | M13: ='Inputs'!C34 | N13: =K13-M13 | O13: =O12+N13
B14: 10 | C14: =ROUND('Inputs'!C40,0) | D14: ='Inputs'!C41 | E14: =C14+D14 | F14: =ROUND(G13*'Inputs'!C42,0) | G14: =G13+E14-F14 | H14: ='Inputs'!C13 | I14: =G14*H14 | J14: =G14*'Inputs'!C27 | K14: =I14-J14 | L14: =IF(I14>0,K14/I14,0) | M14: ='Inputs'!C34 | N14: =K14-M14 | O14: =O13+N14
B15: 11 | C15: =ROUND('Inputs'!C40,0) | D15: ='Inputs'!C41 | E15: =C15+D15 | F15: =ROUND(G14*'Inputs'!C42,0) | G15: =G14+E15-F15 | H15: ='Inputs'!C13 | I15: =G15*H15 | J15: =G15*'Inputs'!C27 | K15: =I15-J15 | L15: =IF(I15>0,K15/I15,0) | M15: ='Inputs'!C34 | N15: =K15-M15 | O15: =O14+N15
B16: 12 | C16: =ROUND('Inputs'!C40,0) | D16: ='Inputs'!C41 | E16: =C16+D16 | F16: =ROUND(G15*'Inputs'!C42,0) | G16: =G15+E16-F16 | H16: ='Inputs'!C13 | I16: =G16*H16 | J16: =G16*'Inputs'!C27 | K16: =I16-J16 | L16: =IF(I16>0,K16/I16,0) | M16: ='Inputs'!C34 | N16: =K16-M16 | O16: =O15+N16
A18: YEAR 1 TOTALS → | I18: =SUM(I5:I16) | J18: =SUM(J5:J16) | K18: =SUM(K5:K16) | M18: =SUM(M5:M16) | N18: =SUM(N5:N16) | O18: =O16
A20: 📊 KEY PERFORMANCE INDICATORS (auto-updated)
B21: Exit Clients (Month 12) | C21: Exit MRR | D21: Exit ARR | E21: Year-1 Net Profit | F21: Break-even Clients | G21: Blended ARPU | H21: COGS per Client | I21: Gross Margin | J21: CAC | K21: LTV | L21: LTV:CAC Ratio
B22: =G16 | C22: =I16 | D22: =I16*12 | E22: =SUM(N5:N16) | F22: =CEILING('Inputs'!C34/('Inputs'!C13-'Inputs'!C27),1) | G22: ='Inputs'!C13 | H22: ='Inputs'!C27 | I22: =IF('Inputs'!C13>0,('Inputs'!C13-'Inputs'!C27)/'Inputs'!C13,0) | J22: =IF('Inputs'!C40>0,'Inputs'!C30/'Inputs'!C40,0) | K22: =(1/'Inputs'!C42)*'Inputs'!C13 | L22: =IF('Inputs'!C40>0,((1/'Inputs'!C42)*'Inputs'!C13)/('Inputs'!C30/'Inputs'!C40),0)

Sheet Unit Economics
A1: 💰 Phone Phoebe — Unit Economics (auto-updates from Inputs)
A2: All calculations pull from Inputs sheet. Change plan prices or COGS there and these update.
A4: A — MARGIN PER PRICING TIER (at typical 90 min/month per client)
B5: Metric | C5: Basic (£39) | D5: Professional (£89) | E5: Premium (£189)
B6: Monthly revenue | C6: ='Inputs'!C5 | D6: ='Inputs'!C6 | E6: ='Inputs'!C7
B7: COGS (cost to serve) | C7: ='Inputs'!C27 | D7: ='Inputs'!C27 | E7: ='Inputs'!C27
B8: Gross profit per client | C8: ='Inputs'!C5-'Inputs'!C27 | D8: ='Inputs'!C6-'Inputs'!C27 | E8: ='Inputs'!C7-'Inputs'!C27
B9: Gross margin % | C9: =IF('Inputs'!C5>0,('Inputs'!C5-'Inputs'!C27)/'Inputs'!C5,0) | D9: =IF('Inputs'!C6>0,('Inputs'!C6-'Inputs'!C27)/'Inputs'!C6,0) | E9: =IF('Inputs'!C7>0,('Inputs'!C7-'Inputs'!C27)/'Inputs'!C7,0)
B10: Monthly cost % of revenue | C10: =IF('Inputs'!C5>0,'Inputs'!C27/'Inputs'!C5,0) | D10: =IF('Inputs'!C6>0,'Inputs'!C27/'Inputs'!C6,0) | E10: =IF('Inputs'!C7>0,'Inputs'!C27/'Inputs'!C7,0)
A12: B — BREAK-EVEN ANALYSIS
B13: Metric | C13: Value | E13: How to read it
B14: Contribution per client (ARPU − COGS) | C14: ='Inputs'!C13-'Inputs'!C27 | E14: Revenue left after direct costs
B15: Fixed overhead per month | C15: ='Inputs'!C34 | E15: Ads + hosting + tools you pay anyway
B16: Clients needed to break even | C16: =CEILING('Inputs'!C34/('Inputs'!C13-'Inputs'!C27),1) | E16: Once you hit this number, you're profitable
B17: Break-even MRR needed | C17: =CEILING('Inputs'!C34/('Inputs'!C13-'Inputs'!C27),1)*'Inputs'!C13 | E17: MRR target to cover all costs
A19: C — CUSTOMER ACQUISITION COST, LIFETIME VALUE & PAYBACK
B20: Metric | C20: Value | E20: Formula / Logic
B21: Cost per lead (from ads) | C21: ='Inputs'!C37 | E21: Set in Inputs → Ad spend ÷ leads
B22: New paid clients per month (from ads) | C22: ='Inputs'!C40 | E22: Leads × trial rate × paid rate
B23: CAC — cost to acquire 1 client | C23: =IF('Inputs'!C40>0,'Inputs'!C30/'Inputs'!C40,0) | E23: Ad spend ÷ new paid clients
B24: Average client lifetime (months) | C24: =IF('Inputs'!C42>0,1/'Inputs'!C42,0) | E24: 1 ÷ churn rate
B25: LTV — lifetime value per client | C25: =IF('Inputs'!C42>0,(1/'Inputs'!C42)*'Inputs'!C13,0) | E25: Lifetime months × ARPU
B26: LTV : CAC ratio (target > 3x) | C26: =IF('Inputs'!C40>0,((1/'Inputs'!C42)*'Inputs'!C13)/('Inputs'!C30/'Inputs'!C40),0) | E26: LTV ÷ CAC | >3x = healthy, >10x = excellent
B27: CAC payback period (months) | C27: =IF('Inputs'!C13>'Inputs'!C27,'Inputs'!C30/'Inputs'!C40/('Inputs'!C13-'Inputs'!C27),0) | E27: Months until CAC is recovered from contribution margin
A29: D — UNLIMITED MINUTES RISK (enter a client's real call volume to stress-test)
B30: Change the yellow 'Average calls per client/month' and 'Average call duration' in Inputs to model a heavier user.
B31: Scenario | C31: Monthly mins | D31: Variable COGS | E31: Total COGS | F31: Still profitable on Basic?
B32: Typical instructor (30 calls × 3 min) | C32: =30*3 | D32: ='Inputs'!C16*30*3 | E32: ='Inputs'!C16*30*3+'Inputs'!C26 | F32: =IF('Inputs'!C5-='Inputs'!C16*30*3+'Inputs'!C26>0,"✅ YES (£"&TEXT('Inputs'!C5-='Inputs'!C16*30*3+'Inputs'!C26,"#,##0")&" margin)","❌ LOSS (£"&TEXT(ABS('Inputs'!C5-='Inputs'!C16*30*3+'Inputs'!C26),"#,##0")&" loss)")
B33: Busy instructor (50 calls × 3 min) | C33: =50*3 | D33: ='Inputs'!C16*50*3 | E33: ='Inputs'!C16*50*3+'Inputs'!C26 | F33: =IF('Inputs'!C5-='Inputs'!C16*50*3+'Inputs'!C26>0,"✅ YES (£"&TEXT('Inputs'!C5-='Inputs'!C16*50*3+'Inputs'!C26,"#,##0")&" margin)","❌ LOSS (£"&TEXT(ABS('Inputs'!C5-='Inputs'!C16*50*3+'Inputs'!C26),"#,##0")&" loss)")
B34: High volume (100 calls × 4 min) | C34: =100*4 | D34: ='Inputs'!C16*100*4 | E34: ='Inputs'!C16*100*4+'Inputs'!C26 | F34: =IF('Inputs'!C5-='Inputs'!C16*100*4+'Inputs'!C26>0,"✅ YES (£"&TEXT('Inputs'!C5-='Inputs'!C16*100*4+'Inputs'!C26,"#,##0")&" margin)","❌ LOSS (£"&TEXT(ABS('Inputs'!C5-='Inputs'!C16*100*4+'Inputs'!C26),"#,##0")&" loss)")
B35: Stress test (200 calls × 5 min) | C35: =200*5 | D35: ='Inputs'!C16*200*5 | E35: ='Inputs'!C16*200*5+'Inputs'!C26 | F35: =IF('Inputs'!C5-='Inputs'!C16*200*5+'Inputs'!C26>0,"✅ YES (£"&TEXT('Inputs'!C5-='Inputs'!C16*200*5+'Inputs'!C26,"#,##0")&" margin)","❌ LOSS (£"&TEXT(ABS('Inputs'!C5-='Inputs'!C16*200*5+'Inputs'!C26),"#,##0")&" loss)")
